Workbook

Sheet Station Info
A1: STATION_NUMBER | B1: STATION_NAME | C1: PROV_TERR_STATE_LOC | D1: REGIONAL_OFFICE_ID | E1: HYD_STATUS | F1: SED_STATUS | G1: LATITUDE | H1: LONGITUDE | I1: DRAINAGE_AREA_GROSS
A2: 10EA003 | B2: FLAT RIVER NEAR THE MOUTH | C2: NT | D2: 9 | E2: ACTIVE | F2: DISCONTINUED | G2: 61.529968 | H2: -125.41075 | I2: 8560
A3: 10EB001 | B3: SOUTH NAHANNI RIVER ABOVE VIRGINIA FALLS | C3: NT | D3: 9 | E3: ACTIVE | G3: 61.636108 | H3: -125.79703 | I3: 14500
A4: 10EC001 | B4: SOUTH NAHANNI RIVER ABOVE CLAUSEN CREEK | C4: NT | D4: 9 | E4: DISCONTINUED | G4: 61.263329 | H4: -124.06972 | I4: 31100
A5: 10ED001 | B5: LIARD RIVER AT FORT LIARD | C5: NT | D5: 9 | E5: ACTIVE | G5: 60.241562 | H5: -123.47542 | I5: 222000

Sheet RFFA
B1: Estimated Regional Maximum Daily Flow for Each Station Using Frequency Analysis
J2: Estimated Maximum Flows for Nahanni River Watershed at Nahanni-Liard Confluence Using Transposition Method
D3: Flood Flows (m3/s)
D4: ='Station Info'!B2 -> FLAT RIVER NEAR THE MOUTH | E4: ='Station Info'!B3 -> SOUTH NAHANNI RIVER ABOVE VIRGINIA FALLS | F4: ='Station Info'!B4 -> SOUTH NAHANNI RIVER ABOVE CLAUSEN CREEK | G4: ='Station Info'!B5 -> LIARD RIVER AT FORT LIARD
C5: Station Name | K5: Maximum Flow (m3/s) | M5: Nahanni River Drainage Area at Nahanni-Liard Confluence | N5: Unit
C6: Station ID | D6: ='Station Info'!A2 -> 10EA003 | E6: ='Station Info'!A3 -> 10EB001 | F6: ='Station Info'!A4 -> 10EC001 | G6: ='Station Info'!A5 -> 10ED001 | J6: Drainage Area (1000 km2) | K6: =M7 -> 36.1
C7: Comment | D7: Medium - Natural | E7: Medium - Natural | F7: Medium - Natural | G7: Large - Cities/Towns | J7: 2-Year | K7: {=EXP(_xlfn.SINGLE(INDEX(LINEST(LN(D8:G8), LN(D$16:G$16)), 2)))*M$7^_xlfn.SINGLE(INDEX(LINEST(LN(D8:G8),LN(D$16:G$16)), 1))} -> 2260.1311 | M7: 36.1 | N7: [1000 km2]
B8: Return Period (Year) | C8: 2 | D8: =VLOOKUP($C8,'10EA003'!$H$19:$J$39,3,FALSE) -> 569 | E8: =VLOOKUP($C8,'10EB001'!$H$19:$J$39,3,FALSE) -> 1420 | F8: =VLOOKUP($C8,'10EC001'!$H$19:$J$39,3,FALSE) -> 2200 | G8: =VLOOKUP($C8,'10ED001'!$H$19:$J$39,3,FALSE) -> 8620 | J8: 5-Year | K8: {=EXP(_xlfn.SINGLE(INDEX(LINEST(LN(D9:G9), LN(D$16:G$16)), 2)))*M$7^_xlfn.SINGLE(INDEX(LINEST(LN(D9:G9),LN(D$16:G$16)), 1))} -> 2857.1078
C9: 5 | D9: =VLOOKUP($C9,'10EA003'!$H$19:$J$39,3,FALSE) -> 803 | E9: =VLOOKUP($C9,'10EB001'!$H$19:$J$39,3,FALSE) -> 1700 | F9: =VLOOKUP($C9,'10EC001'!$H$19:$J$39,3,FALSE) -> 2720 | G9: =VLOOKUP($C9,'10ED001'!$H$19:$J$39,3,FALSE) -> 10700 | J9: 10-Year | K9: {=EXP(_xlfn.SINGLE(INDEX(LINEST(LN(D10:G10), LN(D$16:G$16)), 2)))*M$7^_xlfn.SINGLE(INDEX(LINEST(LN(D10:G10),LN(D$16:G$16)), 1))} -> 3219.1934
C10: 10 | D10: =VLOOKUP($C10,'10EA003'!$H$19:$J$39,3,FALSE) -> 962 | E10: =VLOOKUP($C10,'10EB001'!$H$19:$J$39,3,FALSE) -> 1850 | F10: =VLOOKUP($C10,'10EC001'!$H$19:$J$39,3,FALSE) -> 3050 | G10: =VLOOKUP($C10,'10ED001'!$H$19:$J$39,3,FALSE) -> 11900 | J10: 20-Year | K10: =EXP(INDEX(LINEST(LN(D11:G11), LN(D$16:G$16)), 2))*M$7^INDEX(LINEST(LN(D11:G11),LN(D$16:G$16)), 1) -> 3529.6653
C11: 20 | D11: =VLOOKUP($C11,'10EA003'!$H$19:$J$39,3,FALSE) -> 1120 | E11: =VLOOKUP($C11,'10EB001'!$H$19:$J$39,3,FALSE) -> 1970 | F11: =VLOOKUP($C11,'10EC001'!$H$19:$J$39,3,FALSE) -> 3340 | G11: =VLOOKUP($C11,'10ED001'!$H$19:$J$39,3,FALSE) -> 12800 | J11: 50-Year | K11: =EXP(INDEX(LINEST(LN(D12:G12), LN(D$16:G$16)), 2))*M$7^INDEX(LINEST(LN(D12:G12),LN(D$16:G$16)), 1) -> 3902.0622
C12: 50 | D12: =VLOOKUP($C12,'10EA003'!$H$19:$J$39,3,FALSE) -> 1320 | E12: =VLOOKUP($C12,'10EB001'!$H$19:$J$39,3,FALSE) -> 2110 | F12: =VLOOKUP($C12,'10EC001'!$H$19:$J$39,3,FALSE) -> 3710 | G12: =VLOOKUP($C12,'10ED001'!$H$19:$J$39,3,FALSE) -> 13800 | J12: 100-Year | K12: {=EXP(_xlfn.SINGLE(INDEX(LINEST(LN(D13:G13), LN(D$16:G$16)), 2)))*M$7^_xlfn.SINGLE(INDEX(LINEST(LN(D13:G13),LN(D$16:G$16)), 1))} -> 4171.8095
C13: 100 | D13: =VLOOKUP($C13,'10EA003'!$H$19:$J$39,3,FALSE) -> 1480 | E13: =VLOOKUP($C13,'10EB001'!$H$19:$J$39,3,FALSE) -> 2200 | F13: =VLOOKUP($C13,'10EC001'!$H$19:$J$39,3,FALSE) -> 3980 | G13: =VLOOKUP($C13,'10ED001'!$H$19:$J$39,3,FALSE) -> 14500 | J13: 200-Year | K13: =EXP(INDEX(LINEST(LN(D14:G14), LN(D$16:G$16)), 2))*M$7^INDEX(LINEST(LN(D14:G14),LN(D$16:G$16)), 1) -> 4421.5931
C14: 200 | D14: =VLOOKUP($C14,'10EA003'!$H$19:$J$39,3,FALSE) -> 1630 | E14: =VLOOKUP($C14,'10EB001'!$H$19:$J$39,3,FALSE) -> 2290 | F14: =VLOOKUP($C14,'10EC001'!$H$19:$J$39,3,FALSE) -> 4240 | G14: =VLOOKUP($C14,'10ED001'!$H$19:$J$39,3,FALSE) -> 15100
C15: 2012 | E15: =#REF! -> #REF! | F15: =#REF! -> #REF! | G15: 15315
C16: Drainage Area (1000 km2) | D16: ='Station Info'!I2/1000 -> 8.56 | E16: ='Station Info'!I3/1000 -> 14.5 | F16: ='Station Info'!I4/1000 -> 31.1 | G16: ='Station Info'!I5/1000 -> 222
C17: 100-yr Unit Runoff (m3/s/km2) | D17: =D13/D16 -> 172.8972 | E17: =E13/E16 -> 151.72414 | F17: =F13/F16 -> 127.97428 | G17: =G13/G16 -> 65.315315
C18: Frequency Analysis completed using HYFRAN software, best fit distribution selected based on minimum AIC: see following station specific pages
B21: Regional Maximum Daily Flow vs. Drainage Area Relationship | J21: Estimated Maximum Flows for Liard River Watershed at Nahanni-Liard Confluence Using Transposition Method
K23: Maximum Flow (m3/s) | M23: Liard River Drainage Area at Nahanni-Liard Confluence | N23: Unit
J24: Drainage Area (1000 km2) | K24: =M25 -> 228.8
J25: 2-Year | K25: {=EXP(_xlfn.SINGLE(INDEX(LINEST(LN(D8:G8), LN(D$16:G$16)), 2)))*M$25^_xlfn.SINGLE(INDEX(LINEST(LN(D8:G8),LN(D$16:G$16)), 1))} -> 9511.9046 | M25: 228.8 | N25: [1000 km2]
J26: 5-Year | K26: {=EXP(_xlfn.SINGLE(INDEX(LINEST(LN(D9:G9), LN(D$16:G$16)), 2)))*M$25^_xlfn.SINGLE(INDEX(LINEST(LN(D9:G9),LN(D$16:G$16)), 1))} -> 11539.961
J27: 10-Year | K27: =EXP(INDEX(LINEST(LN(D10:G10), LN(D$16:G$16)), 2))*M$25^INDEX(LINEST(LN(D10:G10),LN(D$16:G$16)), 1) -> 12699.337
J28: 20-Year | K28: =EXP(INDEX(LINEST(LN(D11:G11), LN(D$16:G$16)), 2))*M$25^INDEX(LINEST(LN(D11:G11),LN(D$16:G$16)), 1) -> 13539.93
J29: 50-Year | K29: {=EXP(_xlfn.SINGLE(INDEX(LINEST(LN(D12:G12), LN(D$16:G$16)), 2)))*M$25^_xlfn.SINGLE(INDEX(LINEST(LN(D12:G12),LN(D$16:G$16)), 1))} -> 14490.033
J30: 100-Year | K30: =EXP(INDEX(LINEST(LN(D13:G13), LN(D$16:G$16)), 2))*M$25^INDEX(LINEST(LN(D13:G13),LN(D$16:G$16)), 1) -> 15139.033
J31: 200-Year | K31: =EXP(INDEX(LINEST(LN(D14:G14), LN(D$16:G$16)), 2))*M$25^INDEX(LINEST(LN(D14:G14),LN(D$16:G$16)), 1) -> 15708.638
B53: Regression Analysis of Regional Flood Frequency Statistics (Log-Log)
L62: 20-Year
L63: 100-Year

Sheet 10EA003
A1: Month | B1: Date | C1: Value | E1: Row Labels | F1: Max of Value
A2: =MONTH(B2) -> 6 | B2: 22068 | E2: 1960 | F2: 535 | H2: Rivière Harricana à Amos
A3: =MONTH(B3) -> 6 | B3: 22069 | E3: 1961 | F3: 685
A4: =MONTH(B4) -> 6 | B4: 22070 | E4: 1962 | F4: 555 | H4: Results of the fitting
A5: =MONTH(B5) -> 6 | B5: 22071 | E5: 1963 | F5: 949
A6: =MONTH(B6) -> 6 | B6: 22072 | E6: 1964 | F6: 702 | H6: Lognormal (Maximum Likelihood)
A7: =MONTH(B7) -> 6 | B7: 22073 | E7: 1965 | F7: 445
A8: =MONTH(B8) -> 6 | B8: 22074 | E8: 1966 | F8: 360 | H8: Number of observations 61
A9: =MONTH(B9) -> 6 | B9: 22075 | E9: 1967 | F9: 236
A10: =MONTH(B10) -> 6 | B10: 22076 | E10: 1968 | F10: 835 | H10: Parameters
A11: =MONTH(B11) -> 6 | B11: 22077 | E11: 1969 | F11: 456 | H11: mu | I11: 6.343991
A12: =MONTH(B12) -> 6 | B12: 22078 | E12: 1970 | F12: 221 | H12: sigma | I12: 0.409609
A13: =MONTH(B13) -> 6 | B13: 22079 | E13: 1971 | F13: 501
A14: =MONTH(B14) -> 6 | B14: 22080 | E14: 1972 | F14: 1250 | H14: Quantiles
A15: =MONTH(B15) -> 6 | B15: 22081 | E15: 1973 | F15: 934 | H15: q = F(X) : non-exceedance probability
A16: =MONTH(B16) -> 6 | B16: 22082 | E16: 1974 | F16: 583 | H16: T = 1/(1-q)
A17: =MONTH(B17) -> 6 | B17: 22083 | E17: 1975 | F17: 810
A18: =MONTH(B18) -> 6 | B18: 22084 | E18: 1976 | F18: 453 | H18: T | I18: q | J18: XT | K18: Standard deviation | L18: Confidence interval (95%)
A19: =MONTH(B19) -> 6 | B19: 22085 | E19: 1977 | F19: 467 | H19: 10000 | I19: 0.9999 | J19: 2610 | K19: 388 | L19: 1850 | M19: 3370
A20: =MONTH(B20) -> 6 | B20: 22086 | E20: 1978 | F20: 1100 | H20: 2000 | I20: 0.9995 | J20: 2190 | K20: 293 | L20: 1620 | M20: 2760
A21: =MONTH(B21) -> 6 | B21: 22087 | E21: 1979 | F21: 709 | H21: 1000 | I21: 0.999 | J21: 2020 | K21: 256 | L21: 1520 | M21: 2520
A22: =MONTH(B22) -> 6 | B22: 22088 | E22: 1980 | F22: 527 | H22: 200 | I22: 0.995 | J22: 1630 | K22: 179 | L22: 1280 | M22: 1990
A23: =MONTH(B23) -> 6 | B23: 22089 | E23: 1981 | F23: 486 | H23: 100 | I23: 0.99 | J23: 1480 | K23: 150 | L23: 1180 | M23: 1770
A24: =MONTH(B24) -> 6 | B24: 22090 | E24: 1982 | F24: 555 | H24: 50 | I24: 0.98 | J24: 1320 | K24: 123 | L24: 1080 | M24: 1560
A25: =MONTH(B25) -> 6 | B25: 22091 | E25: 1983 | F25: 300 | H25: 20 | I25: 0.95 | J25: 1120 | K25: 90.3 | L25: 939 | M25: 1290
A26: =MONTH(B26) -> 6 | B26: 22092 | C26: 535 | E26: 1984 | F26: 472 | H26: 10 | I26: 0.9 | J26: 962 | K26: 68.3 | L26: 828 | M26: 1100
A27: =MONTH(B27) -> 6 | B27: 22093 | E27: 1985 | F27: 420 | H27: 5 | I27: 0.8 | J27: 803 | K27: 49.1 | L27: 707 | M27: 900
A28: =MONTH(B28) -> 6 | B28: 22094 | E28: 1986 | F28: 699 | H28: 3 | I28: 0.6667 | J28: 679 | K28: 37.2 | L28: 606 | M28: 752
A29: =MONTH(B29) -> 6 | B29: 22095 | E29: 1987 | F29: 450 | H29: 2 | I29: 0.5 | J29: 569 | K29: 29.8 | L29: 511 | M29: 628
A30: =MONTH(B30) -> 6 | B30: 22096 | E30: 1988 | F30: 640 | H30: 1.4286 | I30: 0.3 | J30: 459 | K30: 25.7 | L30: 409 | M30: 510
A31: =MONTH(B31) -> 6 | B31: 22097 | E31: 1989 | F31: 630 | H31: 1.25 | I31: 0.2 | J31: 403 | K31: 24.7 | L31: 355 | M31: 451
A32: =MONTH(B32) -> 5 | B32: 22402 | E32: 1990 | F32: 810 | H32: 1.1111 | I32: 0.1 | J32: 337 | K32: 23.9 | L32: 290 | M32: 384
A33: =MONTH(B33) -> 5 | B33: 22403 | E33: 1991 | F33: 491 | H33: 1.0526 | I33: 0.05 | J33: 290 | K33: 23.4 | L33: 244 | M33: 336
A34: =MONTH(B34) -> 5 | B34: 22404 | E34: 1992 | F34: 894 | H34: 1.0204 | I34: 0.02 | J34: 245 | K34: 22.8 | L34: 201 | M34: 290
A35: =MONTH(B35) -> 5 | B35: 22405 | E35: 1993 | F35: 384 | H35: 1.0101 | I35: 0.01 | J35: 219 | K35: 22.3 | L35: 176 | M35: 263
A36: =MONTH(B36) -> 5 | B36: 22406 | E36: 1994 | F36: 652 | H36: 1.005 | I36: 0.005 | J36: 198 | K36: 21.7 | L36: 155 | M36: 241
A37: =MONTH(B37) -> 5 | B37: 22407 | E37: 1995 | F37: 265 | H37: 1.001 | I37: 0.001 | J37: 160 | K37: 20.4 | L37: 121 | M37: 200
A38: =MONTH(B38) -> 5 | B38: 22408 | E38: 1996 | F38: 422 | H38: 1.0005 | I38: 0.0005 | J38: 148 | K38: 19.8 | L38: 109 | M38: 187
A39: =MONTH(B39) -> 5 | B39: 22409 | E39: 1997 | F39: 720 | H39: 1.0001 | I39: 0.0001 | J39: 124 | K39: 18.4 | L39: 87.9 | M39: 160
A40: =MONTH(B40) -> 5 | B40: 22410 | E40: 1998 | F40: 371
...

Sheet 10EB001
A1: Month | B1: Date | C1: Value | E1: Row Labels | F1: Max of Value
A2: =MONTH(B2) -> 7 | B2: 22828 | E2: 1962 | F2: 583 | H2: Rivière Harricana à Amos
A3: =MONTH(B3) -> 7 | B3: 22829 | E3: 1963 | F3: 1290
A4: =MONTH(B4) -> 7 | B4: 22830 | E4: 1964 | F4: 1960 | H4: Results of the fitting
A5: =MONTH(B5) -> 7 | B5: 22831 | E5: 1965 | F5: 900
A6: =MONTH(B6) -> 7 | B6: 22832 | E6: 1966 | F6: 1380 | H6: Normal (Maximum Likelihood)
A7: =MONTH(B7) -> 7 | B7: 22833 | E7: 1967 | F7: 1310
A8: =MONTH(B8) -> 7 | B8: 22834 | E8: 1968 | F8: 1320 | H8: Number of observations 58
A9: =MONTH(B9) -> 7 | B9: 22835 | E9: 1969 | F9: 1120
A10: =MONTH(B10) -> 7 | B10: 22836 | E10: 1970 | F10: 1460 | H10: Parameters
A11: =MONTH(B11) -> 7 | B11: 22837 | E11: 1971 | F11: 1250 | H11: mu | I11: 1415.7931
A12: =MONTH(B12) -> 7 | B12: 22838 | E12: 1972 | F12: 2250 | H12: sigma | I12: 338.8252
A13: =MONTH(B13) -> 7 | B13: 22839 | E13: 1973 | F13: 1420
A14: =MONTH(B14) -> 7 | B14: 22840 | E14: 1974 | F14: 964 | H14: Quantiles
A15: =MONTH(B15) -> 7 | B15: 22841 | E15: 1975 | F15: 1840 | H15: q = F(X) : non-exceedance probability
A16: =MONTH(B16) -> 7 | B16: 22842 | E16: 1976 | F16: 1320 | H16: T = 1/(1-q)
A17: =MONTH(B17) -> 7 | B17: 22843 | E17: 1977 | F17: 1120
A18: =MONTH(B18) -> 7 | B18: 22844 | E18: 1978 | F18: 1700 | H18: T | I18: q | J18: XT | K18: Standard deviation | L18: Confidence interval (95%)
A19: =MONTH(B19) -> 7 | B19: 22845 | E19: 1979 | F19: 1310 | H19: 10000 | I19: 0.9999 | J19: 2680 | K19: 126 | L19: 2430 | M19: 2920
A20: =MONTH(B20) -> 7 | B20: 22846 | E20: 1980 | F20: 1200 | H20: 2000 | I20: 0.9995 | J20: 2530 | K20: 114 | L20: 2310 | M20: 2750
A21: =MONTH(B21) -> 7 | B21: 22847 | E21: 1981 | F21: 1340 | H21: 1000 | I21: 0.999 | J21: 2460 | K21: 108 | L21: 2250 | M21: 2670
A22: =MONTH(B22) -> 7 | B22: 22848 | E22: 1982 | F22: 1790 | H22: 200 | I22: 0.995 | J22: 2290 | K22: 93.1 | L22: 2110 | M22: 2470
A23: =MONTH(B23) -> 7 | B23: 22849 | E23: 1983 | F23: 1900 | H23: 100 | I23: 0.99 | J23: 2200 | K23: 86.2 | L23: 2040 | M23: 2370
A24: =MONTH(B24) -> 7 | B24: 22850 | E24: 1984 | F24: 1240 | H24: 50 | I24: 0.98 | J24: 2110 | K24: 78.9 | L24: 1960 | M24: 2270
A25: =MONTH(B25) -> 7 | B25: 22851 | C25: 569 | E25: 1985 | F25: 1750 | H25: 20 | I25: 0.95 | J25: 1970 | K25: 68.6 | L25: 1840 | M25: 2110
A26: =MONTH(B26) -> 7 | B26: 22852 | C26: 549 | E26: 1986 | F26: 1470 | H26: 10 | I26: 0.9 | J26: 1850 | K26: 60.3 | L26: 1730 | M26: 1970
A27: =MONTH(B27) -> 7 | B27: 22853 | C27: 504 | E27: 1987 | F27: 1370 | H27: 5 | I27: 0.8 | J27: 1700 | K27: 51.9 | L27: 1600 | M27: 1800
A28: =MONTH(B28) -> 7 | B28: 22854 | C28: 515 | E28: 1988 | F28: 1350 | H28: 3 | I28: 0.6667 | J28: 1560 | K28: 46.5 | L28: 1470 | M28: 1650
A29: =MONTH(B29) -> 7 | B29: 22855 | C29: 583 | E29: 1989 | F29: 2140 | H29: 2 | I29: 0.5 | J29: 1420 | K29: 44.5 | L29: 1330 | M29: 1500
A30: =MONTH(B30) -> 7 | B30: 22856 | C30: 515 | E30: 1990 | F30: 1910 | H30: 1.4286 | I30: 0.3 | J30: 1240 | K30: 47.5 | L30: 1150 | M30: 1330
A31: =MONTH(B31) -> 7 | B31: 22857 | C31: 493 | E31: 1991 | F31: 1180 | H31: 1.25 | I31: 0.2 | J31: 1130 | K31: 51.9 | L31: 1030 | M31: 1230
A32: =MONTH(B32) -> 7 | B32: 22858 | C32: 544 | E32: 1992 | F32: 1880 | H32: 1.1111 | I32: 0.1 | J32: 982 | K32: 60.3 | L32: 863 | M32: 1100
A33: =MONTH(B33) -> 6 | B33: 23163 | C33: 374 | E33: 1993 | F33: 1790 | H33: 1.0526 | I33: 0.05 | J33: 858 | K33: 68.6 | L33: 724 | M33: 993
A34: =MONTH(B34) -> 6 | B34: 23164 | C34: 394 | E34: 1994 | F34: 1330 | H34: 1.0204 | I34: 0.02 | J34: 720 | K34: 78.9 | L34: 565 | M34: 875
A35: =MONTH(B35) -> 6 | B35: 23165 | C35: 416 | E35: 1995 | F35: 921 | H35: 1.0101 | I35: 0.01 | J35: 627 | K35: 86.2 | L35: 458 | M35: 796
A36: =MONTH(B36) -> 6 | B36: 23166 | C36: 433 | E36: 1996 | F36: 1150 | H36: 1.005 | I36: 0.005 | J36: 543 | K36: 93.1 | L36: 360 | M36: 725
... A39: =MONTH(B39) -> 6 | B39: 23169 | C39: 538 | E39: 1999 | F39: 1450 | H39: 1.0001 | I39: 0.0001 | J39: 156 | K39: 126 | L39: -91.6 | M39: 403
A40: =MONTH(B40) -> 6 | B40: 23170 | C40: 530 | E40: 2000 | F40: 1260
A41: =MONTH(B41) -> 6 | B41: 23171 | C41: 564 | E41: 2001 | F41: 1500
A42: =MONTH(B42) -> 6 | B42: 23172 | C42: 631 | E42: 2002 | F42: 1150
...

Sheet 10EC001
A1: Month | B1: Date | C1: Value | E1: Row Labels | F1: Max of Value
A2: =MONTH(B2) -> 5 | B2: 25324 | E2: 1969 | F2: 1830 | H2: Rivière Harricana à Amos
A3: =MONTH(B3) -> 5 | B3: 25325 | E3: 1970 | F3: 1690
A4: =MONTH(B4) -> 5 | B4: 25326 | E4: 1971 | F4: 1740 | H4: Results of the fitting
A5: =MONTH(B5) -> 5 | B5: 25327 | E5: 1972 | F5: 4750
A6: =MONTH(B6) -> 5 | B6: 25328 | E6: 1973 | F6: 2380 | H6: Lognormal (Maximum Likelihood)
A7: =MONTH(B7) -> 5 | B7: 25329 | E7: 1974 | F7: 2570
A8: =MONTH(B8) -> 5 | B8: 25330 | E8: 1975 | F8: 2800 | H8: Number of observations 27
A9: =MONTH(B9) -> 5 | B9: 25331 | E9: 1976 | F9: 2040
A10: =MONTH(B10) -> 5 | B10: 25332 | E10: 1977 | F10: 1870 | H10: Parameters
A11: =MONTH(B11) -> 5 | B11: 25333 | E11: 1978 | F11: 2920 | H11: mu | I11: 7.695815
A12: =MONTH(B12) -> 5 | B12: 25334 | E12: 1979 | F12: 1920 | H12: sigma | I12: 0.254512
A13: =MONTH(B13) -> 5 | B13: 25335 | E13: 1980 | F13: 1930
A14: =MONTH(B14) -> 5 | B14: 25336 | E14: 1981 | F14: 1900 | H14: Quantiles
A15: =MONTH(B15) -> 5 | B15: 25337 | E15: 1982 | F15: 1910 | H15: q = F(X) : non-exceedance probability
A16: =MONTH(B16) -> 5 | B16: 25338 | E16: 1983 | F16: 2260 | H16: T = 1/(1-q)
A17: =MONTH(B17) -> 5 | B17: 25339 | E17: 1984 | F17: 1970
A18: =MONTH(B18) -> 5 | B18: 25340 | E18: 1985 | F18: 2090 | H18: T | I18: q | J18: XT | K18: Standard deviation | L18: Confidence interval (95%)
A19: =MONTH(B19) -> 5 | B19: 25341 | E19: 1986 | F19: 2230 | H19: 10000 | I19: 0.9999 | J19: 5670 | K19: 794 | L19: 4110 | M19: 7220
A20: =MONTH(B20) -> 5 | B20: 25342 | E20: 1987 | F20: 1780 | H20: 2000 | I20: 0.9995 | J20: 5080 | K20: 641 | L20: 3830 | M20: 6340
A21: =MONTH(B21) -> 5 | B21: 25343 | E21: 1988 | F21: 2170 | H21: 1000 | I21: 0.999 | J21: 4830 | K21: 577 | L21: 3700 | M21: 5960
A22: =MONTH(B22) -> 5 | B22: 25344 | E22: 1989 | F22: 2510 | H22: 200 | I22: 0.995 | J22: 4240 | K22: 438 | L22: 3380 | M22: 5090
A23: =MONTH(B23) -> 5 | B23: 25345 | E23: 1990 | F23: 2780 | H23: 100 | I23: 0.99 | J23: 3980 | K23: 380 | L23: 3230 | M23: 4720
A24: =MONTH(B24) -> 5 | B24: 25346 | E24: 1991 | F24: 1760 | H24: 50 | I24: 0.98 | J24: 3710 | K24: 325 | L24: 3070 | M24: 4350
A25: =MONTH(B25) -> 5 | B25: 25347 | E25: 1992 | F25: 3470 | H25: 20 | I25: 0.95 | J25: 3340 | K25: 254 | L25: 2840 | M25: 3840
A26: =MONTH(B26) -> 5 | B26: 25348 | E26: 1993 | F26: 2320 | H26: 10 | I26: 0.9 | J26: 3050 | K26: 203 | L26: 2650 | M26: 3450
A27: =MONTH(B27) -> 5 | B27: 25349 | E27: 1994 | F27: 2500 | H27: 5 | I27: 0.8 | J27: 2720 | K27: 156 | L27: 2420 | M27: 3030
A28: =MONTH(B28) -> 5 | B28: 25350 | C28: 790 | E28: 1995 | F28: 1340 | H28: 3 | I28: 0.6667 | J28: 2450 | K28: 126 | L28: 2210 | M28: 2700
A29: =MONTH(B29) -> 5 | B29: 25351 | E29: Grand Total | F29: 4750 | H29: 2 | I29: 0.5 | J29: 2200 | K29: 108 | L29: 1990 | M29: 2410
A30: =MONTH(B30) -> 5 | B30: 25352 | H30: 1.4286 | I30: 0.3 | J30: 1920 | K30: 101 | L30: 1730 | M30: 2120
A31: =MONTH(B31) -> 5 | B31: 25353 | H31: 1.25 | I31: 0.2 | J31: 1780 | K31: 102 | L31: 1580 | M31: 1970
A32: =MONTH(B32) -> 5 | B32: 25354 | H32: 1.1111 | I32: 0.1 | J32: 1590 | K32: 106 | L32: 1380 | M32: 1790
A33: =MONTH(B33) -> 6 | B33: 25355 | C33: 700 | H33: 1.0526 | I33: 0.05 | J33: 1450 | K33: 110 | L33: 1230 | M33: 1660
A34: =MONTH(B34) -> 6 | B34: 25356 | C34: 750 | H34: 1.0204 | I34: 0.02 | J34: 1300 | K34: 114 | L34: 1080 | M34: 1530
A35: =MONTH(B35) -> 6 | B35: 25357 | C35: 950 | H35: 1.0101 | I35: 0.01 | J35: 1220 | K35: 116 | L35: 988 | M35: 1440
A36: =MONTH(B36) -> 6 | B36: 25358 | C36: 900 | H36: 1.005 | I36: 0.005 | J36: 1140 | K36: 118 | L36: 910 | M36: 1370
A37: =MONTH(B37) -> 6 | B37: 25359 | C37: 800 | H37: 1.001 | I37: 0.001 | J37: 1000 | K37: 120 | L37: 767 | M37: 1240
A38: =MONTH(B38) -> 6 | B38: 25360 | C38: 878 | H38: 1.0005 | I38: 0.0005 | J38: 952 | K38: 120 | L38: 717 | M38: 1190
A39: =MONTH(B39) -> 6 | B39: 25361 | C39: 1030 | H39: 1.0001 | I39: 0.0001 | J39: 853 | K39: 120 | L39: 619 | M39: 1090
A40: =MONTH(B40) -> 6 | B40: 25362 | C40: 1150
...

Sheet 10ED001
A1: Month | B1: Date | C1: Value | E1: Row Labels | F1: Max of Value
A2: =MONTH(B2) -> 5 | B2: 16193 | C2: 1690 | E2: 1944 | F2: 6230 | H2: Rivière Harricana à Amos
A3: =MONTH(B3) -> 5 | B3: 16194 | C3: 1460 | E3: 1945 | F3: 6770
A4: =MONTH(B4) -> 5 | B4: 16195 | C4: 1780 | E4: 1946 | F4: 5570 | H4: Results of the fitting
A5: =MONTH(B5) -> 5 | B5: 16196 | C5: 1750 | E5: 1947 | F5: 7920
A6: =MONTH(B6) -> 5 | B6: 16197 | C6: 1720 | E6: 1948 | F6: 9710 | H6: Normal (Maximum Likelihood)
A7: =MONTH(B7) -> 5 | B7: 16198 | C7: 1670 | E7: 1949 | F7: 8610
A8: =MONTH(B8) -> 5 | B8: 16199 | C8: 1630 | E8: 1950 | F8: 5610 | H8: Number of observations 75
A9: =MONTH(B9) -> 5 | B9: 16200 | C9: 1530 | E9: 1951 | F9: 8230
A10: =MONTH(B10) -> 5 | B10: 16201 | C10: 1470 | E10: 1952 | F10: 7230 | H10: Parameters
A11: =MONTH(B11) -> 5 | B11: 16202 | C11: 1390 | E11: 1953 | F11: 6050 | H11: mu | I11: 8619.6
A12: =MONTH(B12) -> 5 | B12: 16203 | C12: 1340 | E12: 1954 | F12: 7370 | H12: sigma | I12: 2530.278
A13: =MONTH(B13) -> 5 | B13: 16204 | C13: 1250 | E13: 1955 | F13: 9310
A14: =MONTH(B14) -> 5 | B14: 16205 | C14: 1230 | E14: 1956 | F14: 9500 | H14: Quantiles
A15: =MONTH(B15) -> 5 | B15: 16206 | C15: 1250 | E15: 1957 | F15: 9120 | H15: q = F(X) : non-exceedance probability
A16: =MONTH(B16) -> 5 | B16: 16207 | C16: 1260 | E16: 1958 | F16: 4310 | H16: T = 1/(1-q)
A17: =MONTH(B17) -> 5 | B17: 16208 | C17: 1380 | E17: 1959 | F17: 6800
A18: =MONTH(B18) -> 5 | B18: 16209 | C18: 1510 | E18: 1960 | F18: 8670 | H18: T | I18: q | J18: XT | K18: Standard deviation | L18: Confidence interval (95%)
A19: =MONTH(B19) -> 5 | B19: 16210 | C19: 1720 | E19: 1961 | F19: 12000 | H19: 10000 | I19: 0.9999 | J19: 18000 | K19: 827 | L19: 16400 | M19: 19700
A20: =MONTH(B20) -> 5 | B20: 16211 | C20: 1980 | E20: 1962 | F20: 4530 | H20: 2000 | I20: 0.9995 | J20: 16900 | K20: 744 | L20: 15500 | M20: 18400
A21: =MONTH(B21) -> 5 | B21: 16212 | C21: 2430 | E21: 1966 | F21: 6400 | H21: 1000 | I21: 0.999 | J21: 16400 | K21: 706 | L21: 15100 | M21: 17800
A22: =MONTH(B22) -> 5 | B22: 16213 | C22: 2630 | E22: 1967 | F22: 7330 | H22: 200 | I22: 0.995 | J22: 15100 | K22: 610 | L22: 13900 | M22: 16300
A23: =MONTH(B23) -> 5 | B23: 16214 | C23: 2710 | E23: 1968 | F23: 9090 | H23: 100 | I23: 0.99 | J23: 14500 | K23: 565 | L23: 13400 | M23: 15600
A24: =MONTH(B24) -> 5 | B24: 16215 | C24: 2750 | E24: 1969 | F24: 6230 | H24: 50 | I24: 0.98 | J24: 13800 | K24: 518 | L24: 12800 | M24: 14800
A25: =MONTH(B25) -> 5 | B25: 16216 | C25: 2700 | E25: 1970 | F25: 7840 | H25: 20 | I25: 0.95 | J25: 12800 | K25: 450 | L25: 11900 | M25: 13700
A26: =MONTH(B26) -> 5 | B26: 16217 | C26: 2610 | E26: 1971 | F26: 10400 | H26: 10 | I26: 0.9 | J26: 11900 | K26: 396 | L26: 11100 | M26: 12600
A27: =MONTH(B27) -> 5 | B27: 16218 | C27: 2620 | E27: 1972 | F27: 10000 | H27: 5 | I27: 0.8 | J27: 10700 | K27: 341 | L27: 10100 | M27: 11400
A28: =MONTH(B28) -> 5 | B28: 16219 | C28: 2880 | E28: 1973 | F28: 11300 | H28: 3 | I28: 0.6667 | J28: 9710 | K28: 306 | L28: 9110 | M28: 10300
A29: =MONTH(B29) -> 5 | B29: 16220 | C29: 3100 | E29: 1974 | F29: 12500 | H29: 2 | I29: 0.5 | J29: 8620 | K29: 292 | L29: 8050 | M29: 9190
A30: =MONTH(B30) -> 5 | B30: 16221 | C30: 3340 | E30: 1975 | F30: 12600 | H30: 1.4286 | I30: 0.3 | J30: 7290 | K30: 312 | L30: 6680 | M30: 7910
... A39: =MONTH(B39) -> 6 | B39: 16230 | C39: 4760 | E39: 1984 | F39: 8890 | H39: 1.0001 | I39: 0.0001 | J39: -791 | K39: 827 | L39: -2410 | M39: 830
A40: =MONTH(B40) -> 6 | B40: 16231 | C40: 4780 | E40: 1985 | F40: 7610
A41: =MONTH(B41) -> 6 | B41: 16232 | C41: 4860 | E41: 1986 | F41: 9680
A42: =MONTH(B42) -> 6 | B42: 16233 | C42: 5130 | E42: 1987 | F42: 9320
A43: =MONTH(B43) -> 6 | B43: 16234 | C43: 5340 | E43: 1988 | F43: 14300
A44: =MONTH(B44) -> 6 | B44: 16235 | C44: 5590 | E44: 1989 | F44: 6930
A45: =MONTH(B45) -> 6 | B45: 16236 | C45: 6230 | E45: 1990 | F45: 13400
A46: =MONTH(B46) -> 6 | B46: 16237 | C46: 6210 | E46: 1991 | F46: 7680
A47: =MONTH(B47) -> 6 | B47: 16238 | C47: 5620 | E47: 1992 | F47: 10200
A48: =MONTH(B48) -> 6 | B48: 16239 | C48: 5180 | E48: 1993 | F48: 6090
...
